2022-10-12 18:48:28,392 ERROR frappe Could not take error snapshot: name 'six' is not defined
Site: dcode.com
Form Dict: {}
Traceback (most recent call last):
  File "/home/abhishek/frappe-bench/env/lib/python3.8/site-packages/pymysql/connections.py", line 613, in connect
    sock = socket.create_connection(
  File "/usr/lib/python3.8/socket.py", line 808, in create_connection
    raise err
  File "/usr/lib/python3.8/socket.py", line 796, in create_connection
    sock.connect(sa)
ConnectionRefusedError: [Errno 111] Connection refused

During handling of the above exception, another exception occurred:

Traceback (most recent call last):
  File "/home/abhishek/frappe-bench/apps/frappe/frappe/app.py", line 55, in application
    init_request(request)
  File "/home/abhishek/frappe-bench/apps/frappe/frappe/app.py", line 130, in init_request
    frappe.local.http_request = frappe.auth.HTTPRequest()
  File "/home/abhishek/frappe-bench/apps/frappe/frappe/auth.py", line 37, in __init__
    self.set_session()
  File "/home/abhishek/frappe-bench/apps/frappe/frappe/auth.py", line 74, in set_session
    frappe.local.login_manager = LoginManager()
  File "/home/abhishek/frappe-bench/apps/frappe/frappe/auth.py", line 130, in __init__
    self.make_session(resume=True)
  File "/home/abhishek/frappe-bench/apps/frappe/frappe/auth.py", line 216, in make_session
    frappe.local.session_obj = Session(
  File "/home/abhishek/frappe-bench/apps/frappe/frappe/sessions.py", line 215, in __init__
    self.resume()
  File "/home/abhishek/frappe-bench/apps/frappe/frappe/sessions.py", line 282, in resume
    data = self.get_session_record()
  File "/home/abhishek/frappe-bench/apps/frappe/frappe/sessions.py", line 300, in get_session_record
    r = self.get_session_data()
  File "/home/abhishek/frappe-bench/apps/frappe/frappe/sessions.py", line 316, in get_session_data
    data = self.get_session_data_from_db()
  File "/home/abhishek/frappe-bench/apps/frappe/frappe/sessions.py", line 338, in get_session_data_from_db
    self.device = frappe.db.sql("SELECT `device` FROM `tabSessions` WHERE `sid`=%s", self.sid)
  File "/home/abhishek/frappe-bench/apps/frappe/frappe/database/database.py", line 148, in sql
    self.connect()
  File "/home/abhishek/frappe-bench/apps/frappe/frappe/database/database.py", line 84, in connect
    self._conn = self.get_connection()
  File "/home/abhishek/frappe-bench/apps/frappe/frappe/database/mariadb/database.py", line 76, in get_connection
    conn = pymysql.connect(
  File "/home/abhishek/frappe-bench/env/lib/python3.8/site-packages/pymysql/connections.py", line 353, in __init__
    self.connect()
  File "/home/abhishek/frappe-bench/env/lib/python3.8/site-packages/pymysql/connections.py", line 664, in connect
    raise exc
pymysql.err.OperationalError: (2003, "Can't connect to MySQL server on '127.0.0.1' ([Errno 111] Connection refused)")

During handling of the above exception, another exception occurred:

Traceback (most recent call last):
  File "/home/abhishek/frappe-bench/apps/frappe/frappe/utils/error.py", line 49, in make_error_snapshot
    snapshot = get_snapshot(exception)
  File "/home/abhishek/frappe-bench/apps/frappe/frappe/utils/error.py", line 66, in get_snapshot
    if isinstance(etype, six.class_types):
NameError: name 'six' is not defined
2022-10-19 14:45:54,510 ERROR frappe Could not take error snapshot: name 'six' is not defined
Site: dcode.com
Form Dict: {}
Traceback (most recent call last):
  File "/home/abhishek/frappe-bench/env/lib/python3.8/site-packages/pymysql/connections.py", line 613, in connect
    sock = socket.create_connection(
  File "/usr/lib/python3.8/socket.py", line 808, in create_connection
    raise err
  File "/usr/lib/python3.8/socket.py", line 796, in create_connection
    sock.connect(sa)
ConnectionRefusedError: [Errno 111] Connection refused

During handling of the above exception, another exception occurred:

Traceback (most recent call last):
  File "/home/abhishek/frappe-bench/apps/frappe/frappe/app.py", line 55, in application
    init_request(request)
  File "/home/abhishek/frappe-bench/apps/frappe/frappe/app.py", line 130, in init_request
    frappe.local.http_request = frappe.auth.HTTPRequest()
  File "/home/abhishek/frappe-bench/apps/frappe/frappe/auth.py", line 37, in __init__
    self.set_session()
  File "/home/abhishek/frappe-bench/apps/frappe/frappe/auth.py", line 74, in set_session
    frappe.local.login_manager = LoginManager()
  File "/home/abhishek/frappe-bench/apps/frappe/frappe/auth.py", line 130, in __init__
    self.make_session(resume=True)
  File "/home/abhishek/frappe-bench/apps/frappe/frappe/auth.py", line 216, in make_session
    frappe.local.session_obj = Session(
  File "/home/abhishek/frappe-bench/apps/frappe/frappe/sessions.py", line 215, in __init__
    self.resume()
  File "/home/abhishek/frappe-bench/apps/frappe/frappe/sessions.py", line 287, in resume
    validate_ip_address(self.user)
  File "/home/abhishek/frappe-bench/apps/frappe/frappe/auth.py", line 420, in validate_ip_address
    frappe.get_cached_doc("User", user) if not frappe.flags.in_test else frappe.get_doc("User", user)
  File "/home/abhishek/frappe-bench/apps/frappe/frappe/__init__.py", line 1020, in get_cached_doc
    doc = get_doc(*args, **kwargs)
  File "/home/abhishek/frappe-bench/apps/frappe/frappe/__init__.py", line 1074, in get_doc
    doc = frappe.model.document.get_doc(*args, **kwargs)
  File "/home/abhishek/frappe-bench/apps/frappe/frappe/model/document.py", line 77, in get_doc
    controller = get_controller(doctype)
  File "/home/abhishek/frappe-bench/apps/frappe/frappe/model/base_document.py", line 78, in get_controller
    return _get_controller()
  File "/home/abhishek/frappe-bench/apps/frappe/frappe/model/base_document.py", line 43, in _get_controller
    module_name, custom = frappe.db.get_value(
  File "/home/abhishek/frappe-bench/apps/frappe/frappe/database/database.py", line 459, in get_value
    ret = self.get_values(
  File "/home/abhishek/frappe-bench/apps/frappe/frappe/database/database.py", line 531, in get_values
    out = self._get_values_from_table(
  File "/home/abhishek/frappe-bench/apps/frappe/frappe/database/database.py", line 726, in _get_values_from_table
    r = self.sql(
  File "/home/abhishek/frappe-bench/apps/frappe/frappe/database/database.py", line 148, in sql
    self.connect()
  File "/home/abhishek/frappe-bench/apps/frappe/frappe/database/database.py", line 84, in connect
    self._conn = self.get_connection()
  File "/home/abhishek/frappe-bench/apps/frappe/frappe/database/mariadb/database.py", line 76, in get_connection
    conn = pymysql.connect(
  File "/home/abhishek/frappe-bench/env/lib/python3.8/site-packages/pymysql/connections.py", line 353, in __init__
    self.connect()
  File "/home/abhishek/frappe-bench/env/lib/python3.8/site-packages/pymysql/connections.py", line 664, in connect
    raise exc
pymysql.err.OperationalError: (2003, "Can't connect to MySQL server on '127.0.0.1' ([Errno 111] Connection refused)")

During handling of the above exception, another exception occurred:

Traceback (most recent call last):
  File "/home/abhishek/frappe-bench/apps/frappe/frappe/utils/error.py", line 49, in make_error_snapshot
    snapshot = get_snapshot(exception)
  File "/home/abhishek/frappe-bench/apps/frappe/frappe/utils/error.py", line 66, in get_snapshot
    if isinstance(etype, six.class_types):
NameError: name 'six' is not defined
